Workbook

Sheet Records
A1: Date | B1: Line | C1: Product | D1: Asset | E1: AssetClass | F1: FailureMode_en | G1: FailureMode_ko | H1: ISO14224_Code | I1: Detection_en | J1: Detection_ko | K1: Action_en | L1: Action_ko | M1: Downtime_h | N1: RepairTime_h | O1: Crew1 | P1: Crew2 | Q1: Crew3 | R1: SparePart_SKU | S1: Spare_Qty_OnHand | T1: Reserved_Qty | U1: PartsCost_KRW | V1: LaborCost_KRW | W1: ProdLoss_KRW | X1: TotalCost_KRW | Y1: MTBF_h | Z1: MTTR_h | AA1: Availability | AB1: Detection_Source | AC1: Detection_Method
A2: 45670 | B2: A | C2: AX-01 | D2: ZA2115 Pillow Block | E2: Bearing | F2: Overgreasing causing churning losses | G2: 과윤활로 인한 차닝 손실 | H2: 02-PDE | I2: Temperature rises with no fault frequencies, RMS moderate | J2: 결함 주파수 없이 온도 상승, RMS 중간 수준 | K2: Remove excess grease and set proper quantity | L2: 과잉 그리스 제거 및 적정량 설정 | M2: 2 | N2: 1 | O2: 최가영 | R2: GREASE-NLGI2 | S2: 25 | T2: 0 | U2: =IFERROR(VLOOKUP(R2,'부품 리드타임_가격표'!A:C,3,0)*IF(T2>0,T2,1),0) -> 25000 | V2: =(IFERROR(VLOOKUP(O2,'인력 단가표'!A:C,3,0),0)+IFERROR(VLOOKUP(P2,'인력 단가표'!A:C,3,0),0)+IFERROR(VLOOKUP(Q2,'인력 단가표'!A:C,3,0),0))*N2 -> 42000 | W2: =IFERROR(SUMIFS('라인별 시간당 손실단가'!C:C,'라인별 시간당 손실단가'!A:A,B2,'라인별 시간당 손실단가'!B:B,C2),0)*M2 -> 900000 | X2: =SUM(U2,V2,W2) -> 967000 | Y2: 1420.8 | Z2: 1 | AA2: =IFERROR(Y2/(Y2+Z2),0) -> 0.99929667 | AB2: Analysis | AC2: Temperature monitoring (IR/thermography); Vibration analysis (spectrum/envelope per ISO 20816-3)
A3: 45671 | B3: A | C3: AX-01 | D3: ZA2115 Pillow Block | E3: Bearing | F3: Roller wear due to inadequate lubrication | G3: 윤활 불량으로 인한 롤러 마모 | H3: 02-STD | I3: RMS increased (6.2→9.8 mm/s), rising broadband energy | J3: RMS 상승(6.2→9.8 mm/s), 광대역 에너지 증가 | K3: Grease purge and refill | L3: 그리스 퍼지 후 재주입 | M3: 3 | N3: 2.5 | O3: 김민수 | P3: 박지현 | R3: ZA2115-INSERT | S3: 4 | T3: 1 | U3: =IFERROR(VLOOKUP(R3,'부품 리드타임_가격표'!A:C,3,0)*IF(T3>0,T3,1),0) -> 620000 | V3: =(IFERROR(VLOOKUP(O3,'인력 단가표'!A:C,3,0),0)+IFERROR(VLOOKUP(P3,'인력 단가표'!A:C,3,0),0)+IFERROR(VLOOKUP(Q3,'인력 단가표'!A:C,3,0),0))*N3 -> 250000 | W3: =IFERROR(SUMIFS('라인별 시간당 손실단가'!C:C,'라인별 시간당 손실단가'!A:A,B3,'라인별 시간당 손실단가'!B:B,C3),0)*M3 -> 1350000 | X3: =SUM(U3,V3,W3) -> 2220000 | Y3: 1420.8 | Z3: 2.5 | AA3: =IFERROR(Y3/(Y3+Z3),0) -> 0.99824352 | AB3: Analysis | AC3: Vibration analysis (spectrum/envelope per ISO 20816-3)
A4: 45673 | B4: C | C4: CX-01 | D4: ZA2115 Pillow Block | E4: Bearing | F4: Rotor unbalance affecting bearing load | G4: 로터 언밸런스로 인한 베어링 과하중 | H4: 02-PDE | I4: Dominant 1× rotational peak, phase consistent | J4: 지배적인 1× 회전 피크, 위상 일관 | K4: Balance rotor and verify alignment | L4: 로터 밸런싱 및 정렬 확인 | M4: 4 | N4: 2.5 | O4: 김민수 | S4: 8 | T4: 1 | U4: =IFERROR(VLOOKUP(R4,'부품 리드타임_가격표'!A:C,3,0)*IF(T4>0,T4,1),0) -> 0 | V4: =(IFERROR(VLOOKUP(O4,'인력 단가표'!A:C,3,0),0)+IFERROR(VLOOKUP(P4,'인력 단가표'!A:C,3,0),0)+IFERROR(VLOOKUP(Q4,'인력 단가표'!A:C,3,0),0))*N4 -> 120000 | W4: =IFERROR(SUMIFS('라인별 시간당 손실단가'!C:C,'라인별 시간당 손실단가'!A:A,B4,'라인별 시간당 손실단가'!B:B,C4),0)*M4 -> 1720000 | X4: =SUM(U4,V4,W4) -> 1840000 | Y4: 1584 | Z4: 2.5 | AA4: =IFERROR(Y4/(Y4+Z4),0) -> 0.9984242 | AB4: Analysis | AC4: Vibration analysis (spectrum/envelope per ISO 20816-3)
A5: 45674 | B5: C | C5: CX-01 | D5: ZA2115 Pillow Block | E5: Bearing | F5: Incorrect seal type (clearance vs lip) | G5: 부적절한 씰 타입(클리어런스 vs 립) | H5: 02-INL | I5: Ingress indicators, temperature drift, oil leak traces | J5: 오염 지표, 온도 드리프트, 윤활 누유 흔적 | K5: Change to M Heavy Contact Lip Seal | L5: M 헤비 립 씰로 변경 | M5: 3.5 | N5: 2.5 | O5: 박지현 | R5: M-SEAL-HEAVY | S5: 10 | T5: 2 | U5: =IFERROR(VLOOKUP(R5,'부품 리드타임_가격표'!A:C,3,0)*IF(T5>0,T5,1),0) -> 520000 | V5: =(IFERROR(VLOOKUP(O5,'인력 단가표'!A:C,3,0),0)+IFERROR(VLOOKUP(P5,'인력 단가표'!A:C,3,0),0)+IFERROR(VLOOKUP(Q5,'인력 단가표'!A:C,3,0),0))*N5 -> 130000 | W5: =IFERROR(SUMIFS('라인별 시간당 손실단가'!C:C,'라인별 시간당 손실단가'!A:A,B5,'라인별 시간당 손실단가'!B:B,C5),0)*M5 -> 1505000 | X5: =SUM(U5,V5,W5) -> 2155000 | Y5: 1584 | Z5: 2.5 | AA5: =IFERROR(Y5/(Y5+Z5),0) -> 0.9984242 | AB5: Analysis | AC5: Temperature monitoring (IR/thermography)
A6: 45677 | B6: A | C6: AX-01 | D6: ZA2115 Pillow Block | E6: Bearing | F6: Seal damage → contamination ingress | G6: 씰 파손 → 오염 유입 | H6: 02-INL | I6: Field inspection confirmed seal damage and contamination | J6: 현장 점검으로 씰 손상 및 오염 확인 | K6: Replace seal kit ZS6 and relubricate | L6: ZS6 씰 키트 교체 후 재윤활 | M6: 3 | N6: 2 | O6: 김민수 | R6: ZS6-SEAL | S6: 6 | T6: 1 | U6: =IFERROR(VLOOKUP(R6,'부품 리드타임_가격표'!A:C,3,0)*IF(T6>0,T6,1),0) -> 210000 | V6: =(IFERROR(VLOOKUP(O6,'인력 단가표'!A:C,3,0),0)+IFERROR(VLOOKUP(P6,'인력 단가표'!A:C,3,0),0)+IFERROR(VLOOKUP(Q6,'인력 단가표'!A:C,3,0),0))*N6 -> 96000 | W6: =IFERROR(SUMIFS('라인별 시간당 손실단가'!C:C,'라인별 시간당 손실단가'!A:A,B6,'라인별 시간당 손실단가'!B:B,C6),0)*M6 -> 1350000 | X6: =SUM(U6,V6,W6) -> 1656000 | Y6: 1420.8 | Z6: 2 | AA6: =IFERROR(Y6/(Y6+Z6),0) -> 0.99859432 | AB6: Field | AC6: Infrared thermography
A7: 45685 | B7: B | C7: BX-01 | D7: ZA2115 Pillow Block | E7: Bearing | F7: Housing base crack | G7: 하우징 베이스 크랙 | H7: 02-STD | I7: Visual inspection found base cracking | J7: 육안 점검으로 베이스 크랙 확인 | K7: Replace housing and reinstall base | L7: 하우징 교체 및 베이스 재설치 | M7: 4 | N7: 2.5 | O7: 박지헌 | R7: HOUSING-ZA2115 | S7: 1 | T7: 1 | U7: =IFERROR(VLOOKUP(R7,'부품 리드타임_가격표'!A:C,3,0)*IF(T7>0,T7,1),0) -> 950000 | V7: =(IFERROR(VLOOKUP(O7,'인력 단가표'!A:C,3,0),0)+IFERROR(VLOOKUP(P7,'인력 단가표'!A:C,3,0),0)+IFERROR(VLOOKUP(Q7,'인력 단가표'!A:C,3,0),0))*N7 -> 0 | W7: =IFERROR(SUMIFS('라인별 시간당 손실단가'!C:C,'라인별 시간당 손실단가'!A:A,B7,'라인별 시간당 손실단가'!B:B,C7),0)*M7 -> 1600000 | X7: =SUM(U7,V7,W7) -> 2550000 | Y7: 988.8 | Z7: 2.5 | AA7: =IFERROR(Y7/(Y7+Z7),0) -> 0.99747806 | AB7: Field | AC7: Visual inspection
A8: 45693 | B8: C | C8: CX-01 | D8: ZA2115 Pillow Block | E8: Bearing | F8: Inner ring looseness on shaft | G8: 내륜 샤프트 루즈니스 | H8: 02-SPO | I8: Field check found inner ring movement on shaft | J8: 현장 점검으로 내륜 샤프트 유격 확인 | K8: Install microlock kit and retorque | L8: 마이크로락 키트 장착 및 재토크 | M8: 2.5 | N8: 1.5 | O8: 이현우 | R8: ML2-MICROLOCK | S8: 8 | T8: 1 | U8: =IFERROR(VLOOKUP(R8,'부품 리드타임_가격표'!A:C,3,0)*IF(T8>0,T8,1),0) -> 120000 | V8: =(IFERROR(VLOOKUP(O8,'인력 단가표'!A:C,3,0),0)+IFERROR(VLOOKUP(P8,'인력 단가표'!A:C,3,0),0)+IFERROR(VLOOKUP(Q8,'인력 단가표'!A:C,3,0),0))*N8 -> 67500 | W8: =IFERROR(SUMIFS('라인별 시간당 손실단가'!C:C,'라인별 시간당 손실단가'!A:A,B8,'라인별 시간당 손실단가'!B:B,C8),0)*M8 -> 1075000 | X8: =SUM(U8,V8,W8) -> 1262500 | Y8: 1584 | Z8: 1.5 | AA8: =IFERROR(Y8/(Y8+Z8),0) -> 0.99905393 | AB8: Field | AC8: Field inspection (general)
A9: 45702 | B9: C | C9: CX-01 | D9: ZA2115 Pillow Block | E9: Bearing | F9: Cage wear (BSF) | G9: 케이지 마모(BSF) | H9: 02-STD | I9: BSF 2× and 3× harmonics prominent | J9: BSF 2×, 3× 하모닉 두드러짐 | K9: Replace bearing and clean housing | L9: 베어링 교체 및 하우징 세척 | M9: 5 | N9: 3.5 | O9: 박지현 | R9: ZA2115-SET | S9: 2 | T9: 1 | U9: =IFERROR(VLOOKUP(R9,'부품 리드타임_가격표'!A:C,3,0)*IF(T9>0,T9,1),0) -> 980000 | V9: =(IFERROR(VLOOKUP(O9,'인력 단가표'!A:C,3,0),0)+IFERROR(VLOOKUP(P9,'인력 단가표'!A:C,3,0),0)+IFERROR(VLOOKUP(Q9,'인력 단가표'!A:C,3,0),0))*N9 -> 182000 | W9: =IFERROR(SUMIFS('라인별 시간당 손실단가'!C:C,'라인별 시간당 손실단가'!A:A,B9,'라인별 시간당 손실단가'!B:B,C9),0)*M9 -> 2150000 | X9: =SUM(U9,V9,W9) -> 3312000 | Y9: 1584 | Z9: 3.5 | AA9: =IFERROR(Y9/(Y9+Z9),0) -> 0.99779528 | AB9: Analysis | AC9: Vibration analysis (spectrum/envelope per ISO 20816-3)
A10: 45705 | B10: D | C10: DX-01 | D10: ZA2115 Pillow Block | E10: Bearing | F10: Grease channeling (starvation) | G10: 그리스 채널링(윤활 부족) | H10: 02-PDE | I10: High-frequency peaks, temperature stable, RMS ↑ | J10: 고주파 피크, 온도 안정, RMS 상승 | K10: Re-grease with proper method/time | L10: 적정 방법/주기로 재윤활 | M10: 2.5 | N10: 1.5 | O10: 박지현 | R10: GREASE-NLGI2 | S10: 25 | T10: 0 | U10: =IFERROR(VLOOKUP(R10,'부품 리드타임_가격표'!A:C,3,0)*IF(T10>0,T10,1),0) -> 25000 | V10: =(IFERROR(VLOOKUP(O10,'인력 단가표'!A:C,3,0),0)+IFERROR(VLOOKUP(P10,'인력 단가표'!A:C,3,0),0)+IFERROR(VLOOKUP(Q10,'인력 단가표'!A:C,3,0),0))*N10 -> 78000 | W10: =IFERROR(SUMIFS('라인별 시간당 손실단가'!C:C,'라인별 시간당 손실단가'!A:A,B10,'라인별 시간당 손실단가'!B:B,C10),0)*M10 -> 1025000 | X10: =SUM(U10,V10,W10) -> 1128000 | Y10: 1680 | Z10: 1.5 | AA10: =IFERROR(Y10/(Y10+Z10),0) -> 0.99910794 | AB10: Analysis | AC10: Temperature monitoring (IR/thermography); Vibration analysis (spectrum/envelope per ISO 20816-3)
A11: 45707 | B11: D | C11: DX-01 | D11: ZA2115 Pillow Block | E11: Bearing | F11: Grease channeling (starvation) | G11: 그리스 채널링(윤활 부족) | H11: 02-PDE | I11: On-site lubrication check confirmed starvation | J11: 현장 윤활 점검으로 윤활 부족 확인 | K11: Re-grease with proper method/time | L11: 적정 방법/주기로 재윤활 | M11: 5 | N11: 3 | O11: 최가영 | R11: GREASE-NLGI2 | S11: 25 | T11: 1 | U11: =IFERROR(VLOOKUP(R11,'부품 리드타임_가격표'!A:C,3,0)*IF(T11>0,T11,1),0) -> 25000 | V11: =(IFERROR(VLOOKUP(O11,'인력 단가표'!A:C,3,0),0)+IFERROR(VLOOKUP(P11,'인력 단가표'!A:C,3,0),0)+IFERROR(VLOOKUP(Q11,'인력 단가표'!A:C,3,0),0))*N11 -> 126000 | W11: =IFERROR(SUMIFS('라인별 시간당 손실단가'!C:C,'라인별 시간당 손실단가'!A:A,B11,'라인별 시간당 손실단가'!B:B,C11),0)*M11 -> 2050000 | X11: =SUM(U11,V11,W11) -> 2201000 | Y11: 1680 | Z11: 3 | AA11: =IFERROR(Y11/(Y11+Z11),0) -> 0.99821747 | AB11: Field | AC11: Infrared thermography; Lubrication audit / grease sampling (lab analysis)
A12: 45710 | B12: B | C12: BX-01 | D12: ZA2115 Pillow Block | E12: Bearing | F12: Misalignment (angular/parallel) | G12: 미스얼라인먼트(각도/평행) | H12: 02-PDE | I12: 1× rotational frequency axial peak, phase difference | J12: 1× 회전수 축방향 피크, 위상 차 | K12: Realign and secure base | L12: 정렬 재작업 및 베이스 고정 | M12: 3.5 | N12: 2 | O12: 김민수 | R12: BASE-BOLT-16MM | S12: 40 | T12: 8 | U12: =IFERROR(VLOOKUP(R12,'부품 리드타임_가격표'!A:C,3,0)*IF(T12>0,T12,1),0) -> 40000 | V12: =(IFERROR(VLOOKUP(O12,'인력 단가표'!A:C,3,0),0)+IFERROR(VLOOKUP(P12,'인력 단가표'!A:C,3,0),0)+IFERROR(VLOOKUP(Q12,'인력 단가표'!A:C,3,0),0))*N12 -> 96000 | W12: =IFERROR(SUMIFS('라인별 시간당 손실단가'!C:C,'라인별 시간당 손실단가'!A:A,B12,'라인별 시간당 손실단가'!B:B,C12),0)*M12 -> 1400000 | X12: =SUM(U12,V12,W12) -> 1536000 | Y12: 988.8 | Z12: 2 | AA12: =IFERROR(Y12/(Y12+Z12),0) -> 0.99798143 | AB12: Analysis | AC12: Vibration analysis (spectrum/envelope per ISO 20816-3)
A13: 45715 | B13: A | C13: AX-01 | D13: ZA2115 Pillow Block | E13: Bearing | F13: FTF (cage) defect | G13: FTF(케이지) 결함 | H13: 02-STD | I13: FTF fundamental and 2×, 3× harmonics observed | J13: FTF 기본 및 2×, 3× 하모닉 관측 | K13: Inspect cage and replace if needed | L13: 케이지 점검 및 필요 시 교체 | M13: 3 | N13: 2 | O13: 김민수 | R13: ZA2115-SET | S13: 2 | T13: 1 | U13: =IFERROR(VLOOKUP(R13,'부품 리드타임_가격표'!A:C,3,0)*IF(T13>0,T13,1),0) -> 980000 | V13: =(IFERROR(VLOOKUP(O13,'인력 단가표'!A:C,3,0),0)+IFERROR(VLOOKUP(P13,'인력 단가표'!A:C,3,0),0)+IFERROR(VLOOKUP(Q13,'인력 단가표'!A:C,3,0),0))*N13 -> 96000 | W13: =IFERROR(SUMIFS('라인별 시간당 손실단가'!C:C,'라인별 시간당 손실단가'!A:A,B13,'라인별 시간당 손실단가'!B:B,C13),0)*M13 -> 1350000 | X13: =SUM(U13,V13,W13) -> 2426000 | Y13: 1420.8 | Z13: 2 | AA13: =IFERROR(Y13/(Y13+Z13),0) -> 0.99859432 | AB13: Analysis | AC13: Vibration analysis (spectrum/envelope per ISO 20816-3)
A14: 45721 | B14: A | C14: AX-01 | D14: ZA2115 Pillow Block | E14: Bearing | F14: Incorrect seal type (clearance vs lip) | G14: 부적절한 씰 타입(클리어런스 vs 립) | H14: 02-INL | I14: Seal type verified on-site; mismatch confirmed | J14: 현장에서 씰 타입 확인; 부적합 확인 | K14: Change to M Heavy Contact Lip Seal | L14: M 헤비 립 씰로 변경 | M14: 3.5 | N14: 2 | O14: 문서현 | R14: M-SEAL-HEAVY | S14: 10 | T14: 1 | U14: =IFERROR(VLOOKUP(R14,'부품 리드타임_가격표'!A:C,3,0)*IF(T14>0,T14,1),0) -> 260000 | V14: =(IFERROR(VLOOKUP(O14,'인력 단가표'!A:C,3,0),0)+IFERROR(VLOOKUP(P14,'인력 단가표'!A:C,3,0),0)+IFERROR(VLOOKUP(Q14,'인력 단가표'!A:C,3,0),0))*N14 -> 110000 | W14: =IFERROR(SUMIFS('라인별 시간당 손실단가'!C:C,'라인별 시간당 손실단가'!A:A,B14,'라인별 시간당 손실단가'!B:B,C14),0)*M14 -> 1575000 | X14: =SUM(U14,V14,W14) -> 1945000 | Y14: 1420.8 | Z14: 2 | AA14: =IFERROR(Y14/(Y14+Z14),0) -> 0.99859432 | AB14: Field | AC14: Infrared thermography
A15: 45729 | B15: D | C15: DX-01 | D15: ZA2115 Pillow Block | E15: Bearing | F15: Grease aging/hardening | G15: 그리스 노화/경화 | H15: 02-PDE | I15: High RMS at low frequency, TAN/oxidation indicators | J15: 저주파 RMS 상승, 산가/산화 지표 상승 | K15: Purge old grease and refill (NLGI #2) | L15: 구 그리스 퍼지 후 재주입(NLGI #2) | M15: 2.5 | N15: 2 | O15: 최가영 | R15: GREASE-NLGI2 | S15: 25 | T15: 3 | U15: =IFERROR(VLOOKUP(R15,'부품 리드타임_가격표'!A:C,3,0)*IF(T15>0,T15,1),0) -> 75000 | V15: =(IFERROR(VLOOKUP(O15,'인력 단가표'!A:C,3,0),0)+IFERROR(VLOOKUP(P15,'인력 단가표'!A:C,3,0),0)+IFERROR(VLOOKUP(Q15,'인력 단가표'!A:C,3,0),0))*N15 -> 84000 | W15: =IFERROR(SUMIFS('라인별 시간당 손실단가'!C:C,'라인별 시간당 손실단가'!A:A,B15,'라인별 시간당 손실단가'!B:B,C15),0)*M15 -> 1025000 | X15: =SUM(U15,V15,W15) -> 1184000 | Y15: 1680 | Z15: 2 | AA15: =IFERROR(Y15/(Y15+Z15),0) -> 0.99881094 | AB15: Analysis | AC15: Vibration analysis (spectrum/envelope per ISO 20816-3)
A16: 45738 | B16: B | C16: BX-01 | D16: ZA2115 Pillow Block | E16: Bearing | F16: Rotor unbalance affecting bearing load | G16: 로터 언밸런스로 인한 베어링 과하중 | H16: 02-PDE | I16: Field balancing trial confirmed unbalance | J16: 현장 밸런싱 트라이얼로 언밸런스 확인 | K16: Balance rotor and verify alignment | L16: 로터 밸런싱 및 정렬 확인 | M16: 6 | N16: 3.5 | O16: 김민수 | P16: 박지헌 | S16: 0 | T16: 0 | U16: =IFERROR(VLOOKUP(R16,'부품 리드타임_가격표'!A:C,3,0)*IF(T16>0,T16,1),0) -> 0 | V16: =(IFERROR(VLOOKUP(O16,'인력 단가표'!A:C,3,0),0)+IFERROR(VLOOKUP(P16,'인력 단가표'!A:C,3,0),0)+IFERROR(VLOOKUP(Q16,'인력 단가표'!A:C,3,0),0))*N16 -> 168000 | W16: =IFERROR(SUMIFS('라인별 시간당 손실단가'!C:C,'라인별 시간당 손실단가'!A:A,B16,'라인별 시간당 손실단가'!B:B,C16),0)*M16 -> 2400000 | X16: =SUM(U16,V16,W16) -> 2568000 | Y16: 988.8 | Z16: 3.5 | AA16: =IFERROR(Y16/(Y16+Z16),0) -> 0.99647284 | AB16: Field | AC16: In-situ balancing trial; Infrared thermography
A17: 45755 | B17: C | C17: CX-01 | D17: ZA2115 Pillow Block | E17: Bearing | F17: Shaft step wear | G17: 샤프트 스텝 마모 | H17: 02-STD | I17: Visual/IR inspection confirmed shaft step wear | J17: 육안/IR 점검으로 샤프트 스텝 마모 확인 | K17: Polish shaft and replace bearing | L17: 샤프트 연마 및 베어링 교체 | M17: 7 | N17: 4 | O17: 김민수 | P17: 이현우 | R17: ZA2115-SET | S17: 2 | T17: 1 | U17: =IFERROR(VLOOKUP(R17,'부품 리드타임_가격표'!A:C,3,0)*IF(T17>0,T17,1),0) -> 980000 | V17: =(IFERROR(VLOOKUP(O17,'인력 단가표'!A:C,3,0),0)+IFERROR(VLOOKUP(P17,'인력 단가표'!A:C,3,0),0)+IFERROR(VLOOKUP(Q17,'인력 단가표'!A:C,3,0),0))*N17 -> 372000 | W17: =IFERROR(SUMIFS('라인별 시간당 손실단가'!C:C,'라인별 시간당 손실단가'!A:A,B17,'라인별 시간당 손실단가'!B:B,C17),0)*M17 -> 3010000 | X17: =SUM(U17,V17,W17) -> 4362000 | Y17: 1584 | Z17: 4 | AA17: =IFERROR(Y17/(Y17+Z17),0) -> 0.99748111 | AB17: Field | AC17: Infrared thermography; Visual inspection
A18: 45759 | B18: B | C18: BX-01 | D18: ZA2115 Pillow Block | E18: Bearing | F18: Contamination (water ingress) | G18: 오염(수분 유입) | H18: 02-INL | I18: Particle count ↑, moisture % ↑, broadband energy | J18: 입자 오염도↑, 수분 함량↑, 광대역 에너지 | K18: Replace seals to Viton and flush grease | L18: Viton 씰로 교체 및 그리스 플러시 | M18: 3 | N18: 2 | O18: 이현우 | R18: VITON-SEAL | S18: 5 | T18: 1 | U18: =IFERROR(VLOOKUP(R18,'부품 리드타임_가격표'!A:C,3,0)*IF(T18>0,T18,1),0) -> 180000 | V18: =(IFERROR(VLOOKUP(O18,'인력 단가표'!A:C,3,0),0)+IFERROR(VLOOKUP(P18,'인력 단가표'!A:C,3,0),0)+IFERROR(VLOOKUP(Q18,'인력 단가표'!A:C,3,0),0))*N18 -> 90000 | W18: =IFERROR(SUMIFS('라인별 시간당 손실단가'!C:C,'라인별 시간당 손실단가'!A:A,B18,'라인별 시간당 손실단가'!B:B,C18),0)*M18 -> 1200000 | X18: =SUM(U18,V18,W18) -> 1470000 | Y18: 988.8 | Z18: 2 | AA18: =IFERROR(Y18/(Y18+Z18),0) -> 0.99798143 | AB18: Analysis | AC18: Moisture analysis (ASTM D6304 Karl Fischer); Oil particle counting (ISO 4406); Vibration analysis (spectrum/envelope per ISO 20816-3)
A19: 45765 | B19: D | C19: DX-01 | D19: ZA2115 Pillow Block | E19: Bearing | F19: Grease aging/hardening | G19: 그리스 노화/경화 | H19: 02-PDE | I19: Grease sampling showed aging/hardening | J19: 그리스 샘플링으로 노화/경화 확인 | K19: Purge old grease and refill (NLGI #2) | L19: 구 그리스 퍼지 후 재주입(NLGI #2) | M19: 2 | N19: 1.5 | O19: 박지헌 | P19: 문서현 | R19: GREASE-NLGI2 | S19: 25 | T19: 1 | U19: =IFERROR(VLOOKUP(R19,'부품 리드타임_가격표'!A:C,3,0)*IF(T19>0,T19,1),0) -> 25000 | V19: =(IFERROR(VLOOKUP(O19,'인력 단가표'!A:C,3,0),0)+IFERROR(VLOOKUP(P19,'인력 단가표'!A:C,3,0),0)+IFERROR(VLOOKUP(Q19,'인력 단가표'!A:C,3,0),0))*N19 -> 82500 | W19: =IFERROR(SUMIFS('라인별 시간당 손실단가'!C:C,'라인별 시간당 손실단가'!A:A,B19,'라인별 시간당 손실단가'!B:B,C19),0)*M19 -> 820000 | X19: =SUM(U19,V19,W19) -> 927500 | Y19: 1680 | Z19: 1.5 | AA19: =IFERROR(Y19/(Y19+Z19),0) -> 0.99910794 | AB19: Field | AC19: Lubrication audit / grease sampling (lab analysis)
A20: 45769 | B20: B | C20: BX-01 | D20: ZA2115 Pillow Block | E20: Bearing | F20: Shaft slip due to loosened setscrew | G20: 세트스크류 풀림으로 인한 샤프트 미끄럼 | H20: 02-SPO | I20: Looseness harmonics (2x, 3x) and BPFI sidebands | J20: 루즈니스 하모닉(2x, 3x) 및 BPFI 사이드밴드 | K20: Retorque setscrew to 36.7 N·m | L20: 세트스크류 재토크(36.7 N·m) | M20: 2 | N20: 1.5 | O20: 이현우 | R20: SC6-COLLAR | S20: 12 | T20: 0 | U20: =IFERROR(VLOOKUP(R20,'부품 리드타임_가격표'!A:C,3,0)*IF(T20>0,T20,1),0) -> 45000 | V20: =(IFERROR(VLOOKUP(O20,'인력 단가표'!A:C,3,0),0)+IFERROR(VLOOKUP(P20,'인력 단가표'!A:C,3,0),0)+IFERROR(VLOOKUP(Q20,'인력 단가표'!A:C,3,0),0))*N20 -> 67500 | W20: =IFERROR(SUMIFS('라인별 시간당 손실단가'!C:C,'라인별 시간당 손실단가'!A:A,B20,'라인별 시간당 손실단가'!B:B,C20),0)*M20 -> 800000 | X20: =SUM(U20,V20,W20) -> 912500 | Y20: 988.8 | Z20: 1.5 | AA20: =IFERROR(Y20/(Y20+Z20),0) -> 0.99848531 | AB20: Analysis | AC20: Vibration analysis (spectrum/envelope per ISO 20816-3)
A21: 45772 | B21: D | C21: DX-01 | D21: ZA2115 Pillow Block | E21: Bearing | F21: Soft foot at base causing misalignment | G21: 베이스 소프트풋으로 인한 미스얼라인먼트 | H21: 02-PDE | I21: High axial vibration, pedestal looseness test failed | J21: 축방향 진동 증가, 베이스 루즈니스 테스트 실패 | K21: Realign and secure base | L21: 정렬 재작업 및 베이스 고정 | M21: 3.5 | N21: 2.5 | O21: 문서현 | R21: BASE-BOLT-16MM | S21: 40 | T21: 5 | U21: =IFERROR(VLOOKUP(R21,'부품 리드타임_가격표'!A:C,3,0)*IF(T21>0,T21,1),0) -> 25000 | V21: =(IFERROR(VLOOKUP(O21,'인력 단가표'!A:C,3,0),0)+IFERROR(VLOOKUP(P21,'인력 단가표'!A:C,3,0),0)+IFERROR(VLOOKUP(Q21,'인력 단가표'!A:C,3,0),0))*N21 -> 137500 | W21: =IFERROR(SUMIFS('라인별 시간당 손실단가'!C:C,'라인별 시간당 손실단가'!A:A,B21,'라인별 시간당 손실단가'!B:B,C21),0)*M21 -> 1435000 | X21: =SUM(U21,V21,W21) -> 1597500 | Y21: 1680 | Z21: 2.5 | AA21: =IFERROR(Y21/(Y21+Z21),0) -> 0.99851412 | AB21: Analysis | AC21: Process/vibration monitoring (general)
A22: 45777 | B22: C | C22: CX-01 | D22: ZA2115 Pillow Block | E22: Bearing | F22: Fretting corrosion at fits | G22: 결합부 프레팅 부식 | H22: 02-STD | I22: Low-frequency broadband with friction tones | J22: 저주파 광대역 및 마찰톤 | K22: Resurface fit and apply anti-fretting compound | L22: 결합부 재가공 및 방지 코팅 적용 | M22: 5 | N22: 3 | O22: 이현우 | R22: ZA2115-INSERT | S22: 3 | T22: 1 | U22: =IFERROR(VLOOKUP(R22,'부품 리드타임_가격표'!A:C,3,0)*IF(T22>0,T22,1),0) -> 620000 | V22: =(IFERROR(VLOOKUP(O22,'인력 단가표'!A:C,3,0),0)+IFERROR(VLOOKUP(P22,'인력 단가표'!A:C,3,0),0)+IFERROR(VLOOKUP(Q22,'인력 단가표'!A:C,3,0),0))*N22 -> 135000 | W22: =IFERROR(SUMIFS('라인별 시간당 손실단가'!C:C,'라인별 시간당 손실단가'!A:A,B22,'라인별 시간당 손실단가'!B:B,C22),0)*M22 -> 2150000 | X22: =SUM(U22,V22,W22) -> 2905000 | Y22: 1584 | Z22: 3 | AA22: =IFERROR(Y22/(Y22+Z22),0) -> 0.99810964 | AB22: Analysis | AC22: Vibration analysis (spectrum/envelope per ISO 20816-3)
A23: 45783 | B23: B | C23: BX-01 | D23: ZA2115 Pillow Block | E23: Bearing | F23: Overload (process upset) | G23: 과하중(공정 이상) | H23: 02-PDE | I23: Temperature ↑, RMS ↑, process pressure spike | J23: 온도↑, RMS↑, 공정 압력 스파이크 | K23: Normalize process and inspect bearing | L23: 공정 정상화 및 베어링 점검 | M23: 4 | N23: 2 | O23: 최가영 | R23: ZA2115-INSERT | S23: 4 | T23: 1 | U23: =IFERROR(VLOOKUP(R23,'부품 리드타임_가격표'!A:C,3,0)*IF(T23>0,T23,1),0) -> 620000 | V23: =(IFERROR(VLOOKUP(O23,'인력 단가표'!A:C,3,0),0)+IFERROR(VLOOKUP(P23,'인력 단가표'!A:C,3,0),0)+IFERROR(VLOOKUP(Q23,'인력 단가표'!A:C,3,0),0))*N23 -> 84000 | W23: =IFERROR(SUMIFS('라인별 시간당 손실단가'!C:C,'라인별 시간당 손실단가'!A:A,B23,'라인별 시간당 손실단가'!B:B,C23),0)*M23 -> 1600000 | X23: =SUM(U23,V23,W23) -> 2304000 | Y23: 988.8 | Z23: 2 | AA23: =IFERROR(Y23/(Y23+Z23),0) -> 0.99798143 | AB23: Analysis | AC23: Temperature monitoring (IR/thermography); Vibration analysis (spectrum/envelope per ISO 20816-3)
A24: 45788 | B24: A | C24: AX-01 | D24: ZA2115 Pillow Block | E24: Bearing | F24: Thermal growth misalignment | G24: 열팽창 미스얼라인먼트 | H24: 02-PDE | I24: Post-warm-up alignment check showed drift | J24: 웜업 후 정렬 점검에서 드리프트 확인 | K24: Realign and secure base | L24: 정렬 재작업 및 베이스 고정 | M24: 4.5 | N24: 3 | O24: 이현우 | P24: 최가영 | R24: BASE-BOLT-16MM | S24: 40 | T24: 1 | U24: =IFERROR(VLOOKUP(R24,'부품 리드타임_가격표'!A:C,3,0)*IF(T24>0,T24,1),0) -> 5000 | V24: =(IFERROR(VLOOKUP(O24,'인력 단가표'!A:C,3,0),0)+IFERROR(VLOOKUP(P24,'인력 단가표'!A:C,3,0),0)+IFERROR(VLOOKUP(Q24,'인력 단가표'!A:C,3,0),0))*N24 -> 261000 | W24: =IFERROR(SUMIFS('라인별 시간당 손실단가'!C:C,'라인별 시간당 손실단가'!A:A,B24,'라인별 시간당 손실단가'!B:B,C24),0)*M24 -> 2025000 | X24: =SUM(U24,V24,W24) -> 2291000 | Y24: 1420.8 | Z24: 3 | AA24: =IFERROR(Y24/(Y24+Z24),0) -> 0.99789296 | AB24: Field | AC24: Laser/dial alignment check
A25: 45798 | B25: A | C25: AX-01 | D25: ZA2115 Pillow Block | E25: Bearing | F25: Inner race spalling (BPFI) | G25: 내륜 스폴링(BPFI) | H25: 02-STD | I25: BPFI peak and sidebands, elevated crest factor | J25: BPFI 피크와 사이드밴드, 크레스트 팩터 상승 | K25: Replace bearing set and inspect shaft | L25: 베어링 세트 교체 및 샤프트 점검 | M25: 7.5 | N25: 5 | O25: 김민수 | P25: 문서현 | R25: ZA2115-SET | S25: 2 | T25: 1 | U25: =IFERROR(VLOOKUP(R25,'부품 리드타임_가격표'!A:C,3,0)*IF(T25>0,T25,1),0) -> 980000 | V25: =(IFERROR(VLOOKUP(O25,'인력 단가표'!A:C,3,0),0)+IFERROR(VLOOKUP(P25,'인력 단가표'!A:C,3,0),0)+IFERROR(VLOOKUP(Q25,'인력 단가표'!A:C,3,0),0))*N25 -> 515000 | W25: =IFERROR(SUMIFS('라인별 시간당 손실단가'!C:C,'라인별 시간당 손실단가'!A:A,B25,'라인별 시간당 손실단가'!B:B,C25),0)*M25 -> 3375000 | X25: =SUM(U25,V25,W25) -> 4870000 | Y25: 1420.8 | Z25: 5 | AA25: =IFERROR(Y25/(Y25+Z25),0) -> 0.9964932 | AB25: Analysis | AC25: Vibration analysis (spectrum/envelope per ISO 20816-3)
A26: 45804 | B26: B | C26: BX-01 | D26: ZA2115 Pillow Block | E26: Bearing | F26: Outer ring pitting (BPFO) | G26: 외륜 피팅(BPFO) | H26: 02-STD | I26: Visual inspection and stethoscope confirmed pitting | J26: 육안 및 스테토스코프 점검으로 피팅 확인 | K26: Replace bearing insert | L26: 베어링 인서트 교체 | M26: 3 | N26: 2 | O26: 문서현 | P26: 김민수 | R26: ZA2115-INSERT | S26: 3 | T26: 1 | U26: =IFERROR(VLOOKUP(R26,'부품 리드타임_가격표'!A:C,3,0)*IF(T26>0,T26,1),0) -> 620000 | V26: =(IFERROR(VLOOKUP(O26,'인력 단가표'!A:C,3,0),0)+IFERROR(VLOOKUP(P26,'인력 단가표'!A:C,3,0),0)+IFERROR(VLOOKUP(Q26,'인력 단가표'!A:C,3,0),0))*N26 -> 206000 | W26: =IFERROR(SUMIFS('라인별 시간당 손실단가'!C:C,'라인별 시간당 손실단가'!A:A,B26,'라인별 시간당 손실단가'!B:B,C26),0)*M26 -> 1200000 | X26: =SUM(U26,V26,W26) -> 2026000 | Y26: 988.8 | Z26: 2 | AA26: =IFERROR(Y26/(Y26+Z26),0) -> 0.99798143 | AB26: Field | AC26: Acoustic listening (stethoscope); Infrared thermography; Visual inspection
A27: 45815 | B27: C | C27: CX-01 | D27: ZA2115 Pillow Block | E27: Bearing | F27: Outer race pitting (BPFO) | G27: 외륜 피팅(BPFO) | H27: 02-STD | I27: BPFO peaks with harmonics, kurtosis increased | J27: BPFO 피크 및 조화, 커토시스 증가 | K27: Replace bearing insert | L27: 베어링 인서트 교체 | M27: 5.5 | N27: 3.5 | O27: 김민수 | R27: ZA2115-INSERT | S27: 3 | T27: 1 | U27: =IFERROR(VLOOKUP(R27,'부품 리드타임_가격표'!A:C,3,0)*IF(T27>0,T27,1),0) -> 620000 | V27: =(IFERROR(VLOOKUP(O27,'인력 단가표'!A:C,3,0),0)+IFERROR(VLOOKUP(P27,'인력 단가표'!A:C,3,0),0)+IFERROR(VLOOKUP(Q27,'인력 단가표'!A:C,3,0),0))*N27 -> 168000 | W27: =IFERROR(SUMIFS('라인별 시간당 손실단가'!C:C,'라인별 시간당 손실단가'!A:A,B27,'라인별 시간당 손실단가'!B:B,C27),0)*M27 -> 2365000 | X27: =SUM(U27,V27,W27) -> 3153000 | Y27: 1584 | Z27: 3.5 | AA27: =IFERROR(Y27/(Y27+Z27),0) -> 0.99779528 | AB27: Analysis | AC27: Vibration analysis (spectrum/envelope per ISO 20816-3)
A28: 45833 | B28: D | C28: DX-01 | D28: ZA2115 Pillow Block | E28: Bearing | F28: Inner race spalling (BPFI) | G28: 내륜 스폴링(BPFI) | H28: 02-STD | I28: BPFI peak and sidebands, elevated crest factor | J28: BPFI 피크와 사이드밴드, 크레스트 팩터 상승 | K28: Replace bearing set and inspect shaft | L28: 베어링 세트 교체 및 샤프트 점검 | M28: 6.5 | N28: 4.5 | O28: 박지헌 | R28: ZA2115-SET | S28: 2 | T28: 1 | U28: =IFERROR(VLOOKUP(R28,'부품 리드타임_가격표'!A:C,3,0)*IF(T28>0,T28,1),0) -> 980000 | V28: =(IFERROR(VLOOKUP(O28,'인력 단가표'!A:C,3,0),0)+IFERROR(VLOOKUP(P28,'인력 단가표'!A:C,3,0),0)+IFERROR(VLOOKUP(Q28,'인력 단가표'!A:C,3,0),0))*N28 -> 0 | W28: =IFERROR(SUMIFS('라인별 시간당 손실단가'!C:C,'라인별 시간당 손실단가'!A:A,B28,'라인별 시간당 손실단가'!B:B,C28),0)*M28 -> 2665000 | X28: =SUM(U28,V28,W28) -> 3645000 | Y28: 1680 | Z28: 4.5 | AA28: =IFERROR(Y28/(Y28+Z28),0) -> 0.99732858 | AB28: Analysis | AC28: Vibration analysis (spectrum/envelope per ISO 20816-3)
A29: 45847 | B29: A | C29: AX-01 | D29: ZA2115 Pillow Block | E29: Bearing | F29: Cage wear (BSF) | G29: 케이지 마모(BSF) | H29: 02-STD | I29: FTF fundamental and 2×, 3× harmonics observed | J29: FTF 기본 및 2×, 3× 하모닉 관측 | K29: Replace bearing and clean housing | L29: 베어링 교체 및 하우징 세척 | M29: 3 | N29: 2 | O29: 이현우 | R29: ZA2115-SET | S29: 2 | T29: 1 | U29: =IFERROR(VLOOKUP(R29,'부품 리드타임_가격표'!A:C,3,0)*IF(T29>0,T29,1),0) -> 980000 | V29: =(IFERROR(VLOOKUP(O29,'인력 단가표'!A:C,3,0),0)+IFERROR(VLOOKUP(P29,'인력 단가표'!A:C,3,0),0)+IFERROR(VLOOKUP(Q29,'인력 단가표'!A:C,3,0),0))*N29 -> 90000 | W29: =IFERROR(SUMIFS('라인별 시간당 손실단가'!C:C,'라인별 시간당 손실단가'!A:A,B29,'라인별 시간당 손실단가'!B:B,C29),0)*M29 -> 1350000 | X29: =SUM(U29,V29,W29) -> 2420000 | Y29: 1420.8 | Z29: 2 | AA29: =IFERROR(Y29/(Y29+Z29),0) -> 0.99859432 | AB29: Analysis | AC29: Vibration analysis (spectrum/envelope per ISO 20816-3)
A30: 45862 | B30: B | C30: BX-01 | D30: ZA2115 Pillow Block | E30: Bearing | F30: FTF (cage) defect | G30: FTF(케이지) 결함 | H30: 02-STD | I30: FTF fundamental and 2×, 3× harmonics observed | J30: FTF 기본 및 2×, 3× 하모닉 관측 | K30: Inspect cage and replace if needed | L30: 케이지 점검 및 필요 시 교체 | M30: 2.5 | N30: 1.5 | O30: 최가영 | R30: ZA2115-SET | S30: 2 | T30: 1 | U30: =IFERROR(VLOOKUP(R30,'부품 리드타임_가격표'!A:C,3,0)*IF(T30>0,T30,1),0) -> 980000 | V30: =(IFERROR(VLOOKUP(O30,'인력 단가표'!A:C,3,0),0)+IFERROR(VLOOKUP(P30,'인력 단가표'!A:C,3,0),0)+IFERROR(VLOOKUP(Q30,'인력 단가표'!A:C,3,0),0))*N30 -> 63000 | W30: =IFERROR(SUMIFS('라인별 시간당 손실단가'!C:C,'라인별 시간당 손실단가'!A:A,B30,'라인별 시간당 손실단가'!B:B,C30),0)*M30 -> 1000000 | X30: =SUM(U30,V30,W30) -> 2043000 | Y30: 988.8 | Z30: 1.5 | AA30: =IFERROR(Y30/(Y30+Z30),0) -> 0.99848531 | AB30: Analysis | AC30: Vibration analysis (spectrum/envelope per ISO 20816-3)
A31: 45874 | B31: B | C31: BX-01 | D31: ZA2115 Pillow Block | E31: Bearing | F31: Thermal growth misalignment | G31: 열팽창 미스얼라인먼트 | H31: 02-PDE | I31: Alignment drifts after warm-up; phase change | J31: 워밍업 후 정렬 드리프트; 위상 변화 | K31: Realign and secure base | L31: 정렬 재작업 및 베이스 고정 | M31: 3 | N31: 2 | O31: 문서현 | R31: BASE-BOLT-16MM | S31: 40 | T31: 6 | U31: =IFERROR(VLOOKUP(R31,'부품 리드타임_가격표'!A:C,3,0)*IF(T31>0,T31,1),0) -> 30000 | V31: =(IFERROR(VLOOKUP(O31,'인력 단가표'!A:C,3,0),0)+IFERROR(VLOOKUP(P31,'인력 단가표'!A:C,3,0),0)+IFERROR(VLOOKUP(Q31,'인력 단가표'!A:C,3,0),0))*N31 -> 110000 | W31: =IFERROR(SUMIFS('라인별 시간당 손실단가'!C:C,'라인별 시간당 손실단가'!A:A,B31,'라인별 시간당 손실단가'!B:B,C31),0)*M31 -> 1200000 | X31: =SUM(U31,V31,W31) -> 1340000 | Y31: 988.8 | Z31: 2 | AA31: =IFERROR(Y31/(Y31+Z31),0) -> 0.99798143 | AB31: Analysis | AC31: Process/vibration monitoring (general)
A32: 45881 | B32: C | C32: CX-01 | D32: ZA2115 Pillow Block | E32: Bearing | F32: Misalignment (angular/parallel) | G32: 미스얼라인먼트(각도/평행) | H32: 02-PDE | I32: 1× rotational axial peak, phase difference | J32: 1× 회전수 축방향 피크, 위상 차 | K32: Realign and secure base | L32: 정렬 재작업 및 베이스 고정 | M32: 4 | N32: 2.5 | O32: 문서현 | R32: BASE-BOLT-16MM | S32: 40 | T32: 1 | U32: =IFERROR(VLOOKUP(R32,'부품 리드타임_가격표'!A:C,3,0)*IF(T32>0,T32,1),0) -> 5000 | V32: =(IFERROR(VLOOKUP(O32,'인력 단가표'!A:C,3,0),0)+IFERROR(VLOOKUP(P32,'인력 단가표'!A:C,3,0),0)+IFERROR(VLOOKUP(Q32,'인력 단가표'!A:C,3,0),0))*N32 -> 137500 | W32: =IFERROR(SUMIFS('라인별 시간당 손실단가'!C:C,'라인별 시간당 손실단가'!A:A,B32,'라인별 시간당 손실단가'!B:B,C32),0)*M32 -> 1720000 | X32: =SUM(U32,V32,W32) -> 1862500 | Y32: 1584 | Z32: 2.5 | AA32: =IFERROR(Y32/(Y32+Z32),0) -> 0.9984242 | AB32: Analysis | AC32: Vibration analysis (spectrum/envelope per ISO 20816-3)
A33: 45897 | B33: D | C33: DX-01 | D33: ZA2115 Pillow Block | E33: Bearing | F33: Shaft slip due to loosened setscrew | G33: 세트스크류 풀림으로 인한 샤프트 미끄럼 | H33: 02-SPO | I33: Looseness harmonics (2×, 3×) and BPFI sidebands | J33: 루즈니스 하모닉(2×, 3×) 및 BPFI 사이드밴드 | K33: Retorque setscrew to 36.7 N·m | L33: 세트스크류 재토크(36.7 N·m) | M33: 3.5 | N33: 2 | O33: 김민수 | P33: 박지헌 | R33: SC6-COLLAR | S33: 12 | T33: 1 | U33: =IFERROR(VLOOKUP(R33,'부품 리드타임_가격표'!A:C,3,0)*IF(T33>0,T33,1),0) -> 45000 | V33: =(IFERROR(VLOOKUP(O33,'인력 단가표'!A:C,3,0),0)+IFERROR(VLOOKUP(P33,'인력 단가표'!A:C,3,0),0)+IFERROR(VLOOKUP(Q33,'인력 단가표'!A:C,3,0),0))*N33 -> 96000 | W33: =IFERROR(SUMIFS('라인별 시간당 손실단가'!C:C,'라인별 시간당 손실단가'!A:A,B33,'라인별 시간당 손실단가'!B:B,C33),0)*M33 -> 1435000 | X33: =SUM(U33,V33,W33) -> 1576000 | Y33: 1680 | Z33: 2 | AA33: =IFERROR(Y33/(Y33+Z33),0) -> 0.99881094 | AB33: Analysis | AC33: Vibration analysis (spectrum/envelope per ISO 20816-3)
A34: 45912 | B34: A | C34: AX-01 | D34: ZA2115 Pillow Block | E34: Bearing | F34: Contamination (water ingress) | G34: 오염(수분 유입) | H34: 02-INL | I34: Particle count ↑, moisture % ↑, broadband energy | J34: 입자수 ↑, 수분함량 ↑, 광대역 에너지 | K34: Replace seal kit ZS6 and flush grease | L34: ZS6 씰 키트 교체 후 그리스 플러시 | M34: 6 | N34: 3.5 | O34: 김민수 | P34: 이현우 | R34: ZS6-SEAL | S34: 6 | T34: 1 | U34: =IFERROR(VLOOKUP(R34,'부품 리드타임_가격표'!A:C,3,0)*IF(T34>0,T34,1),0) -> 210000 | V34: =(IFERROR(VLOOKUP(O34,'인력 단가표'!A:C,3,0),0)+IFERROR(VLOOKUP(P34,'인력 단가표'!A:C,3,0),0)+IFERROR(VLOOKUP(Q34,'인력 단가표'!A:C,3,0),0))*N34 -> 325500 | W34: =IFERROR(SUMIFS('라인별 시간당 손실단가'!C:C,'라인별 시간당 손실단가'!A:A,B34,'라인별 시간당 손실단가'!B:B,C34),0)*M34 -> 2700000 | X34: =SUM(U34,V34,W34) -> 3235500 | Y34: 1420.8 | Z34: 3.5 | AA34: =IFERROR(Y34/(Y34+Z34),0) -> 0.99754265 | AB34: Analysis | AC34: Moisture analysis (ASTM D6304 Karl Fischer); Oil particle counting (ISO 4406); Vibration analysis (spectrum/envelope per ISO 20816-3)
A35: 45916 | B35: B | C35: BX-01 | D35: ZA2115 Pillow Block | E35: Bearing | F35: Housing base crack | G35: 하우징 베이스 크랙 | H35: 02-STD | I35: Low-frequency resonance, rising temperature at housing | J35: 저주파 공진, 하우징 온도 상승 | K35: Replace housing and reinstall base | L35: 하우징 교체 및 베이스 재설치 | M35: 8 | N35: 5.5 | O35: 문서현 | P35: 박지현 | R35: HOUSING-ZA2115 | S35: 1 | T35: 0 | U35: =IFERROR(VLOOKUP(R35,'부품 리드타임_가격표'!A:C,3,0)*IF(T35>0,T35,1),0) -> 950000 | V35: =(IFERROR(VLOOKUP(O35,'인력 단가표'!A:C,3,0),0)+IFERROR(VLOOKUP(P35,'인력 단가표'!A:C,3,0),0)+IFERROR(VLOOKUP(Q35,'인력 단가표'!A:C,3,0),0))*N35 -> 588500 | W35: =IFERROR(SUMIFS('라인별 시간당 손실단가'!C:C,'라인별 시간당 손실단가'!A:A,B35,'라인별 시간당 손실단가'!B:B,C35),0)*M35 -> 3200000 | X35: =SUM(U35,V35,W35) -> 4738500 | Y35: 988.8 | Z35: 5.5 | AA35: =IFERROR(Y35/(Y35+Z35),0) -> 0.99446847 | AB35: Analysis | AC35: Temperature monitoring (IR/thermography)
A36: 45927 | B36: B | C36: BX-01 | D36: ZA2115 Pillow Block | E36: Bearing | F36: Overgreasing causing churning losses | G36: 과윤활로 인한 차덩 손실 | H36: 02-PDE | I36: Temperature rises with no fault frequencies, RMS moderate | J36: 결함 주파수 없이 온도 상승, RMS 중간 수준 | K36: Remove excess grease and set proper quantity | L36: 과잉 그리스 제거 및 적정량 설정 | M36: 2 | N36: 1.5 | O36: 박지헌 | P36: 문서현 | R36: GREASE-NLGI2 | S36: 25 | T36: 1 | U36: =IFERROR(VLOOKUP(R36,'부품 리드타임_가격표'!A:C,3,0)*IF(T36>0,T36,1),0) -> 25000 | V36: =(IFERROR(VLOOKUP(O36,'인력 단가표'!A:C,3,0),0)+IFERROR(VLOOKUP(P36,'인력 단가표'!A:C,3,0),0)+IFERROR(VLOOKUP(Q36,'인력 단가표'!A:C,3,0),0))*N36 -> 82500 | W36: =IFERROR(SUMIFS('라인별 시간당 손실단가'!C:C,'라인별 시간당 손실단가'!A:A,B36,'라인별 시간당 손실단가'!B:B,C36),0)*M36 -> 800000 | X36: =SUM(U36,V36,W36) -> 907500 | Y36: 988.8 | Z36: 1.5 | AA36: =IFERROR(Y36/(Y36+Z36),0) -> 0.99848531 | AB36: Analysis | AC36: Temperature monitoring (IR/thermography); Vibration analysis (spectrum/envelope per ISO 20816-3)
A37: 45937 | B37: C | C37: CX-01 | D37: ZA2115 Pillow Block | E37: Bearing | F37: Outer race pitting (BPFO) | G37: 외륜 피팅(BPFO) | H37: 02-STD | I37: BPFO peaks with harmonics, kurtosis increased | J37: BPFO 피크 및 조화, 커토시스 증가 | K37: Replace bearing insert | L37: 베어링 인서트 교체 | M37: 6 | N37: 4 | O37: 박지현 | P37: 최가영 | R37: ZA2115-INSERT | S37: 3 | T37: 1 | U37: =IFERROR(VLOOKUP(R37,'부품 리드타임_가격표'!A:C,3,0)*IF(T37>0,T37,1),0) -> 620000 | V37: =(IFERROR(VLOOKUP(O37,'인력 단가표'!A:C,3,0),0)+IFERROR(VLOOKUP(P37,'인력 단가표'!A:C,3,0),0)+IFERROR(VLOOKUP(Q37,'인력 단가표'!A:C,3,0),0))*N37 -> 376000 | W37: =IFERROR(SUMIFS('라인별 시간당 손실단가'!C:C,'라인별 시간당 손실단가'!A:A,B37,'라인별 시간당 손실단가'!B:B,C37),0)*M37 -> 2580000 | X37: =SUM(U37,V37,W37) -> 3576000 | Y37: 1584 | Z37: 4 | AA37: =IFERROR(Y37/(Y37+Z37),0) -> 0.99748111 | AB37: Analysis | AC37: Vibration analysis (spectrum/envelope per ISO 20816-3)
A38: 45945 | B38: A | C38: AX-01 | D38: ZA2115 Pillow Block | E38: Bearing | F38: Inner ring looseness on shaft | G38: 내륜 샤프트 루즈니스 | H38: 02-SPO | I38: Sidebands around 1×, modulation, phase instability | J38: 1× 주변 사이드밴드, 변조, 위상 불안정 | K38: Install microlock kit and retorque | L38: 마이크로락 키트 장착 및 재토크 | M38: 3 | N38: 2 | O38: 문서현 | R38: ML2-MICROLOCK | S38: 8 | T38: 1 | U38: =IFERROR(VLOOKUP(R38,'부품 리드타임_가격표'!A:C,3,0)*IF(T38>0,T38,1),0) -> 120000 | V38: =(IFERROR(VLOOKUP(O38,'인력 단가표'!A:C,3,0),0)+IFERROR(VLOOKUP(P38,'인력 단가표'!A:C,3,0),0)+IFERROR(VLOOKUP(Q38,'인력 단가표'!A:C,3,0),0))*N38 -> 110000 | W38: =IFERROR(SUMIFS('라인별 시간당 손실단가'!C:C,'라인별 시간당 손실단가'!A:A,B38,'라인별 시간당 손실단가'!B:B,C38),0)*M38 -> 1350000 | X38: =SUM(U38,V38,W38) -> 1580000 | Y38: 1420.8 | Z38: 2 | AA38: =IFERROR(Y38/(Y38+Z38),0) -> 0.99859432 | AB38: Analysis | AC38: Vibration analysis (spectrum/envelope per ISO 20816-3)
A39: 45960 | B39: D | C39: DX-01 | D39: ZA2115 Pillow Block | E39: Bearing | F39: Seal damage → contamination ingress | G39: 씰 파손 → 오염 유입 | H39: 02-INL | I39: Temperature increased (76→93°C), particle count high | J39: 온도 상승(76→93°C), 입자 오염도 증가 | K39: Replace seal kit ZS6 and relubricate | L39: ZS6 씰 키트 교체 후 재윤활 | M39: 4 | N39: 3 | O39: 이현우 | R39: ZS6-SEAL | S39: 6 | T39: 1 | U39: =IFERROR(VLOOKUP(R39,'부품 리드타임_가격표'!A:C,3,0)*IF(T39>0,T39,1),0) -> 210000 | V39: =(IFERROR(VLOOKUP(O39,'인력 단가표'!A:C,3,0),0)+IFERROR(VLOOKUP(P39,'인력 단가표'!A:C,3,0),0)+IFERROR(VLOOKUP(Q39,'인력 단가표'!A:C,3,0),0))*N39 -> 135000 | W39: =IFERROR(SUMIFS('라인별 시간당 손실단가'!C:C,'라인별 시간당 손실단가'!A:A,B39,'라인별 시간당 손실단가'!B:B,C39),0)*M39 -> 1640000 | X39: =SUM(U39,V39,W39) -> 1985000 | Y39: 1680 | Z39: 3 | AA39: =IFERROR(Y39/(Y39+Z39),0) -> 0.99821747 | AB39: Analysis | AC39: Oil particle counting (ISO 4406); Temperature monitoring (IR/thermography)
A40: 45966 | B40: A | C40: AX-01 | D40: ZA2115 Pillow Block | E40: Bearing | F40: Shaft step wear | G40: 샤프트 스텝 마모 | H40: 02-STD | I40: Crest factor increased, spectral asymmetry | J40: 크레스트 팩터 증가, 스펙트럼 비대칭 | K40: Polish shaft and replace bearing | L40: 샤프트 연마 및 베어링 교체 | M40: 6.5 | N40: 4.5 | O40: 김민수 | P40: 이현우 | R40: SHAFT-49MM | S40: 1 | T40: 1 | U40: =IFERROR(VLOOKUP(R40,'부품 리드타임_가격표'!A:C,3,0)*IF(T40>0,T40,1),0) -> 820000 | V40: =(IFERROR(VLOOKUP(O40,'인력 단가표'!A:C,3,0),0)+IFERROR(VLOOKUP(P40,'인력 단가표'!A:C,3,0),0)+IFERROR(VLOOKUP(Q40,'인력 단가표'!A:C,3,0),0))*N40 -> 418500 | W40: =IFERROR(SUMIFS('라인별 시간당 손실단가'!C:C,'라인별 시간당 손실단가'!A:A,B40,'라인별 시간당 손실단가'!B:B,C40),0)*M40 -> 2925000 | X40: =SUM(U40,V40,W40) -> 4163500 | Y40: 1420.8 | Z40: 4.5 | AA40: =IFERROR(Y40/(Y40+Z40),0) -> 0.99684277 | AB40: Analysis | AC40: Vibration analysis (spectrum/envelope per ISO 20816-3)
...

Sheet 라인별 시간당 손실단가
A1: Line | B1: Product | C1: HourlyLoss_KRW
A2: A | B2: AX-01 | C2: 450000
A3: B | B3: BX-01 | C3: 400000
A4: C | B4: CX-01 | C4: 430000
A5: D | B5: DX-01 | C5: 410000

Sheet 부품 리드타임_가격표
A1: SKU | B1: PartName | C1: UnitPrice_KRW | D1: LeadTime_days | E1: Supplier
A2: ZA2115-INSERT | B2: Bearing Insert | C2: 620000 | D2: 5 | E2: Rexnord
A3: 2115U-INSERT | B3: Bearing Insert (2115U) | C3: 650000 | D3: 5 | E3: Rexnord
A4: ZA2115-SET | B4: Bearing Set | C4: 980000 | D4: 7 | E4: Rexnord
A5: ZS6-SEAL | B5: Seal Kit ZS6 | C5: 210000 | D5: 3 | E5: Rexnord
A6: SC6-COLLAR | B6: Setscrew Collar | C6: 45000 | D6: 2 | E6: Rexnord
A7: BASE-BOLT-16MM | B7: Base Bolt 16mm | C7: 5000 | D7: 2 | E7: Local
A8: GREASE-NLGI2 | B8: Grease NLGI #2 | C8: 25000 | D8: 1 | E8: Local
A9: SHAFT-49MM | B9: Shaft Ø49mm | C9: 820000 | D9: 10 | E9: Local
A10: HOUSING-ZA2115 | B10: Housing ZA2115 | C10: 950000 | D10: 7 | E10: Rexnord
A11: ML2-MICROLOCK | B11: Microlock Kit ML2 | C11: 120000 | D11: 4 | E11: Rexnord
A12: DTC6-ENDCAP | B12: End Cap DTC6 | C12: 140000 | D12: 4 | E12: Rexnord
A13: VITON-SEAL | B13: Viton Seal | C13: 180000 | D13: 3 | E13: Rexnord
... A15: M-SEAL-HEAVY | B15: M Heavy Contact Lip Seal | C15: 260000 | D15: 5 | E15: Rexnord

Sheet 인력 단가표
A1: Name | B1: Role | C1: Rate_KRW_per_h
A2: 김민수 | B2: Sr. Technician | C2: 48000
A3: 박지현 | B3: Vibration Analyst | C3: 52000
A4: 이현우 | B4: Mechanic | C4: 45000
A5: 최가영 | B5: Lubrication Tech | C5: 42000
A6: 문서현 | B6: Field Engineer | C6: 55000

Sheet ISO14224_Codes
A1: AssetClass | B1: Code | C1: Description_en | D1: Description_ko | E1: Source
A2: Bearing | B2: 01-FTS | C2: Failure to start on demand | D2: 요구 시 기동 실패 | E2: ISO 14224 (normative terminology)
A3: Bearing | B3: 02-STD | C3: Structural deficiency (crack/wear/corrosion) | D3: 구조적 결함(크랙/마모/부식) | E3: ISO 14224 (examples)
A4: Bearing | B4: 02-PDE | C4: Parameter deviation (out-of-tolerance alignment/vibration) | D4: 매개변수 편차(정렬/진동 허용치 초과) | E4: ISO 14224 (examples)
A5: Bearing | B5: 02-PLU | C5: Plugged/Choked (flow restriction due contamination) | D5: 플러그/막힘(오염으로 유로 제한) | E5: ISO 14224 (examples)
A6: Motor | B6: 01-FTI | C6: Failure to function as intended | D6: 의도된 기능 수행 실패 | E6: ISO 14224 (normative terminology)
A7: Motor | B7: 02-SPO | C7: Spurious operation (unexpected start/stop) | D7: 예상치 못한 동작(스퓨리어스) | E7: ISO 14224 (examples)
A8: Pump | B8: 01-FTS | C8: Failure to start on demand | D8: 요구 시 기동 실패 | E8: ISO 14224 (normative terminology)
A9: Pump | B9: 02-STD | C9: Structural deficiency (impeller/bearing damage) | D9: 구조적 결함(임펠러/베어링 손상) | E9: ISO 14224 (examples)
A10: Generic | B10: 02-INL | C10: Internal leakage (seal/packing failure) | D10: 내부 누설(씰/패킹 문제) | E10: ISO 14224 (examples)
A11: Generic | B11: 02-IHT | C11: Insufficient heat transfer (cooling/lube condition) | D11: 열전달 부족(냉각/윤활 상태) | E11: ISO 14224 (examples)
A12: Generic | B12: 02-SPO | C12: Spurious operation | D12: 예상치 못한 동작 | E12: ISO 14224 (examples)
A13: Generic | B13: 02-PDE | C13: Parameter deviation (pressure/flow deviates) | D13: 매개변수 편차(압력/유량 편차) | E13: ISO 14224 (examples)

Sheet Notes
A1: 설명(Notes)
A2: SKU: Stock Keeping Unit의 약어로, 자재/부품을 고유 식별하는 내부 코드. ERP/CMMS에서 구매/재고/리드타임/가격 연계에 사용.
A3: Spare_Qty_OnHand: 현재 창고에 물리적으로 보유 중인 사용 가능 수량.
A4: Reserved_Qty: 작업지시/예약으로 묶여 즉시 사용 불가한 수량. 실제 가용 수량 = OnHand - Reserved.
A5: MTBF/MTTR/Availability: 라인별 평균 고장 간격(시), 수리시간(시), 가동률=MTBF/(MTBF+MTTR). 이번 버전은 라인 고정 MTBF를 Records에 기재하고, 레코드별 MTTR로 가동률을 계산.
